Workbook
Name Slicer_Department1: #N/A
Name Slicer_Priority1: #N/A
Name Slicer_Status: #N/A

Sheet Instructions
B2: Project Management Analytics — Practice Project
B3: Excel project: Power Query · Excel Functions · PivotTables · Power Pivot (Data Model + DAX) · Dashboard
B5: Scenario
B6: You work as a Data Analyst supporting the PMO (Project Management Office) of a company running 15 parallel projects. Task-level data is exported from the old tracking tool and is messy: inconsistent text casing, extra spaces, mixed date formats, duplicate rows, and missing values. Your job is to clean the data, model it properly, build the analysis with formulas and PivotTables, then create a Power Pivot data model with DAX measures and present the results in a one-page interactive dashboard.
B10: Workbook Contents
B11: Instructions | D11: This sheet — the full task brief and deliverables checklist.
B12: Projects | D12: Master list of 15 projects (source table for Power Query / Power Pivot).
B13: Employees | D13: Master list of staff with department and hourly rate (source table).
B14: Tasks_RawData | D14: Messy raw task export — the main table you will clean in Power Query.
B15: PQ_Output (you create) | D15: Destination sheet/table for your cleaned Power Query output.
B16: PivotTables (you create) | D16: Sheet(s) for your PivotTable analysis.
B17: Dashboard (you create) | D17: Final one-page interactive dashboard.
B19: PART 1 — POWER QUERY (Data Cleaning & Shaping)
B20: • | C20: Import the Tasks_RawData table into Power Query (Data > Get Data > From Table/Range).
B21: • | C21: Remove exact duplicate rows.
B22: • | C22: Remove the 4 placeholder/test rows (Task_Name = "TEST - ignore").
B23: • | C23: Trim and Clean all text columns (remove leading/trailing/extra spaces).
B24: • | C24: Standardize the Department column to exactly: IT, Operations, Finance, Marketing, HR, Procurement, Quality Assurance (fix casing/abbreviations such as "it", "I.T", "Ops", "QA").
B25: • | C25: Standardize the Status column to exactly: Not Started, In Progress, Completed, Delayed (fix casing and synonyms such as "Pending", "Ongoing", "Done", "Behind Schedule").
B26: • | C26: Standardize the Priority column to exactly: High, Medium, Low (fix casing and single-letter codes H/M/L).
B27: • | C27: Convert Start_Date, Planned_End_Date and Actual_End_Date to a proper Date data type (the raw export mixes several date text formats).
B28: • | C28: Handle blanks: replace missing Planned_Cost / Actual_Cost with 0; replace missing Priority with "Not Set"; replace missing Assigned_To with "Unassigned".
B29: • | C29: Add a calculated column Planned_Duration_Days = Planned_End_Date − Start_Date.
B30: • | C30: Add a calculated column Delay_Days = Actual_End_Date − Planned_End_Date (blank/0 if not completed).
B31: • | C31: Merge (left outer join) with the Projects table on Project_ID to bring in Project_Manager, Client and Budget.
... B34: • | C34: Load the cleaned result to a new sheet as an Excel Table named tbl_Tasks_Clean, AND load a copy to the Data Model (checkbox in the Load To dialog) for Part 4.
B36: PART 2 — EXCEL FUNCTIONS
B37: • | C37: Work on your cleaned table (tbl_Tasks_Clean). Add the following helper columns using formulas (not hardcoded values):
B38: • | C38: Cost_Variance = Actual_Cost − Planned_Cost.
B39: • | C39: Cost_Variance_% = Cost_Variance / Planned_Cost, using IFERROR to handle any Planned_Cost = 0.
B40: • | C40: On_Time_Flag: use IF to return "On Time" when Status = "Completed" and Delay_Days <= 0, "Late" when Status = "Completed" and Delay_Days > 0, and "N/A" otherwise.
B41: • | C41: Task_Age_Category: use IFS (or nested IF) to bucket Planned_Duration_Days into "Short (<=7 days)", "Medium (8-20 days)", "Long (>20 days)".
B42: • | C42: Manager_Lookup: use INDEX/MATCH (not VLOOKUP) to pull Project_Manager from the Projects sheet by Project_ID, as a second, independent check on your Power Query merge.
B43: • | C43: Build a small Summary block (separate area of the same sheet or a new sheet) using:
B44: • | C44: • COUNTIFS — count of Delayed tasks per Department.
B45: • | C45: • SUMIFS — total Actual_Cost per Department for Completed tasks.
B46: • | C46: • AVERAGEIFS — average Delay_Days per Priority level, for Completed/Delayed tasks only.
B47: • | C47: • A TEXT + DATEDIF-based formula that produces a readable string such as "Delayed by 5 days" from Delay_Days.
B49: PART 3 — PIVOTTABLES
B50: • | C50: Create a new sheet called PivotTables and build at least 4 PivotTables (or one PivotTable with multiple value fields, plus 3 focused ones) from tbl_Tasks_Clean:
...

Sheet Summary 
A1: Department | B1: Delayed_Task_Count | C1: Completed_Actual_Cost | D1: Priority | E1: Avg_Delay_Completed | F1: Avg_Delay_Delayed
A2: IT | B2: =COUNTIFS(tbl_Tasks_Clean[Department],A2,tbl_Tasks_Clean[Status],"Delayed") -> 7 | C2: =SUMIFS(tbl_Tasks_Clean[Actual_Cost],tbl_Tasks_Clean[Department],A2,tbl_Tasks_Clean[Status],"Completed") -> 72262 | D2: High | E2: =AVERAGEIFS(tbl_Tasks_Clean[Delay_Days],tbl_Tasks_Clean[Priority],D2,tbl_Tasks_Clean[Status],"Completed") -> 0.19230769 | F2: =AVERAGEIFS(tbl_Tasks_Clean[Delay_Days],tbl_Tasks_Clean[Priority],D2,tbl_Tasks_Clean[Status],"Delayed") -> 5.2142857
A3: Operations | B3: =COUNTIFS(tbl_Tasks_Clean[Department],A3,tbl_Tasks_Clean[Status],"Delayed") -> 3 | C3: =SUMIFS(tbl_Tasks_Clean[Actual_Cost],tbl_Tasks_Clean[Department],A3,tbl_Tasks_Clean[Status],"Completed") -> 77808 | D3: Medium | E3: =AVERAGEIFS(tbl_Tasks_Clean[Delay_Days],tbl_Tasks_Clean[Priority],D3,tbl_Tasks_Clean[Status],"Completed") -> -0.17647059 | F3: =AVERAGEIFS(tbl_Tasks_Clean[Delay_Days],tbl_Tasks_Clean[Priority],D3,tbl_Tasks_Clean[Status],"Delayed") -> 5.8461538
A4: Finance | B4: =COUNTIFS(tbl_Tasks_Clean[Department],A4,tbl_Tasks_Clean[Status],"Delayed") -> 0 | C4: =SUMIFS(tbl_Tasks_Clean[Actual_Cost],tbl_Tasks_Clean[Department],A4,tbl_Tasks_Clean[Status],"Completed") -> 0 | D4: Low | E4: =AVERAGEIFS(tbl_Tasks_Clean[Delay_Days],tbl_Tasks_Clean[Priority],D4,tbl_Tasks_Clean[Status],"Completed") -> -0.72222222 | F4: =AVERAGEIFS(tbl_Tasks_Clean[Delay_Days],tbl_Tasks_Clean[Priority],D4,tbl_Tasks_Clean[Status],"Delayed") -> 2.3
A5: Marketing | B5: =COUNTIFS(tbl_Tasks_Clean[Department],A5,tbl_Tasks_Clean[Status],"Delayed") -> 0 | C5: =SUMIFS(tbl_Tasks_Clean[Actual_Cost],tbl_Tasks_Clean[Department],A5,tbl_Tasks_Clean[Status],"Completed") -> 0
A6: HR | B6: =COUNTIFS(tbl_Tasks_Clean[Department],A6,tbl_Tasks_Clean[Status],"Delayed") -> 0 | C6: =SUMIFS(tbl_Tasks_Clean[Actual_Cost],tbl_Tasks_Clean[Department],A6,tbl_Tasks_Clean[Status],"Completed") -> 0
A7: Procurement | B7: =COUNTIFS(tbl_Tasks_Clean[Department],A7,tbl_Tasks_Clean[Status],"Delayed") -> 6 | C7: =SUMIFS(tbl_Tasks_Clean[Actual_Cost],tbl_Tasks_Clean[Department],A7,tbl_Tasks_Clean[Status],"Completed") -> 53046
A8: Quality Assurance | B8: =COUNTIFS(tbl_Tasks_Clean[Department],A8,tbl_Tasks_Clean[Status],"Delayed") -> 0 | C8: =SUMIFS(tbl_Tasks_Clean[Actual_Cost],tbl_Tasks_Clean[Department],A8,tbl_Tasks_Clean[Status],"Completed") -> 0

Sheet tbl_Projects
A1: Project_ID | B1: Project_Name | C1: Client | D1: Project_Manager | E1: Start_Date | F1: Budget
A2: PRJ-001 | B2: Website Redesign | C2: Nile Corp | D2: Mona Farid | E2: 45455 | F2: 75000
A3: PRJ-002 | B3: ERP System Rollout | C3: Delta Retail Group | D3: Youssef Adel | E3: 45481 | F3: 150000
A4: PRJ-003 | B4: Mobile App Launch | C4: Alexandria Logistics | D4: Ahmed Nabil | E4: 45349 | F4: 100000
A5: PRJ-004 | B5: Warehouse Automation | C5: Cairo Financial Services | D5: Laila Samir | E5: 45465 | F5: 75000
A6: PRJ-005 | B6: Customer Portal Upgrade | C6: Horizon Manufacturing | D6: Ahmed Nabil | E6: 45300 | F6: 50000
A7: PRJ-006 | B7: CRM Migration | C7: BlueWave Telecom | D7: Mona Farid | E7: 45347 | F7: 120000
A8: PRJ-007 | B8: Network Security Overhaul | C8: Internal | D8: Laila Samir | E8: 45435 | F8: 120000
A9: PRJ-008 | B9: Office Relocation | C9: Pharos Holdings | D9: Nourhan Tarek | E9: 45348 | F9: 300000
A10: PRJ-009 | B10: Supply Chain Optimization | C10: Suez Trading Co. | D10: Laila Samir | E10: 45293 | F10: 100000
A11: PRJ-010 | B11: Product Line Expansion | C11: Internal | D11: Sara Hassan | E11: 45379 | F11: 150000
A12: PRJ-011 | B12: HR System Implementation | C12: Giza Health Systems | D12: Ahmed Nabil | E12: 45347 | F12: 200000
A13: PRJ-012 | B13: Cloud Migration | C13: Red Sea Tourism | D13: Ahmed Nabil | E13: 45315 | F13: 250000
... A16: PRJ-015 | B16: Data Center Upgrade | C16: Internal | D16: Nourhan Tarek | E16: 45388 | F16: 75000

Sheet Projects
A1: Project_ID | B1: Project_Name | C1: Client | D1: Project_Manager | E1: Start_Date | F1: Budget
A2: PRJ-001 | B2: Website Redesign | C2: Nile Corp | D2: Mona Farid | E2: 2024-06-12 | F2: 75000
A3: PRJ-002 | B3: ERP System Rollout | C3: Delta Retail Group | D3: Youssef Adel | E3: 2024-07-08 | F3: 150000
A4: PRJ-003 | B4: Mobile App Launch | C4: Alexandria Logistics | D4: Ahmed Nabil | E4: 2024-02-27 | F4: 100000
A5: PRJ-004 | B5: Warehouse Automation | C5: Cairo Financial Services | D5: Laila Samir | E5: 2024-06-22 | F5: 75000
A6: PRJ-005 | B6: Customer Portal Upgrade | C6: Horizon Manufacturing | D6: Ahmed Nabil | E6: 2024-01-09 | F6: 50000
A7: PRJ-006 | B7: CRM Migration | C7: BlueWave Telecom | D7: Mona Farid | E7: 2024-02-25 | F7: 120000
A8: PRJ-007 | B8: Network Security Overhaul | C8: Internal | D8: Laila Samir | E8: 2024-05-23 | F8: 120000
A9: PRJ-008 | B9: Office Relocation | C9: Pharos Holdings | D9: Nourhan Tarek | E9: 2024-02-26 | F9: 300000
A10: PRJ-009 | B10: Supply Chain Optimization | C10: Suez Trading Co. | D10: Laila Samir | E10: 2024-01-02 | F10: 100000
A11: PRJ-010 | B11: Product Line Expansion | C11: Internal | D11: Sara Hassan | E11: 2024-03-28 | F11: 150000
A12: PRJ-011 | B12: HR System Implementation | C12: Giza Health Systems | D12: Ahmed Nabil | E12: 2024-02-25 | F12: 200000
A13: PRJ-012 | B13: Cloud Migration | C13: Red Sea Tourism | D13: Ahmed Nabil | E13: 2024-01-24 | F13: 250000
... A16: PRJ-015 | B16: Data Center Upgrade | C16: Internal | D16: Nourhan Tarek | E16: 2024-04-06 | F16: 75000

Sheet tbl_Employees
A1: Employee_ID | B1: Employee_Name | C1: Department | D1: Role | E1: Hourly_Rate
A2: EMP-001 | B2: Hana Zaki | C2: IT | D2: Systems Analyst | E2: 150
A3: EMP-002 | B3: Yasmin Younes | C3: IT | D3: Systems Analyst | E3: 220
A4: EMP-003 | B4: Hassan Fouad | C4: IT | D4: Software Engineer | E4: 280
A5: EMP-004 | B5: Tarek Abdelrahman | C5: IT | D5: IT Support Specialist | E5: 180
A6: EMP-005 | B6: Dina Zaki | C6: IT | D6: Systems Analyst | E6: 220
A7: EMP-006 | B7: Farida Younes | C7: Operations | D7: Operations Coordinator | E7: 180
A8: EMP-007 | B8: Reem Gaber | C8: Operations | D8: Operations Coordinator | E8: 180
A9: EMP-008 | B9: Sherif Hosny | C9: Operations | D9: Logistics Planner | E9: 200
A10: EMP-009 | B10: Farida Zaki | C10: Operations | D10: Operations Coordinator | E10: 200
A11: EMP-010 | B11: Yasmin Zaki | C11: Operations | D11: Logistics Planner | E11: 220
A12: EMP-011 | B12: Khaled Naguib | C12: Finance | D12: Budget Controller | E12: 250
A13: EMP-012 | B13: Khaled Younes | C13: Finance | D13: Accountant | E13: 280
... A28: EMP-027 | B28: Salma Fouad | C28: Quality Assurance | D28: QA Engineer | E28: 200

Sheet Employees
A1: Employee_ID | B1: Employee_Name | C1: Department | D1: Role | E1: Hourly_Rate
A2: EMP-001 | B2: Hana Zaki | C2: IT | D2: Systems Analyst | E2: 150
A3: EMP-002 | B3: Yasmin Younes | C3: IT | D3: Systems Analyst | E3: 220
A4: EMP-003 | B4: Hassan Fouad | C4: IT | D4: Software Engineer | E4: 280
A5: EMP-004 | B5: Tarek Abdelrahman | C5: IT | D5: IT Support Specialist | E5: 180
A6: EMP-005 | B6: Dina Zaki | C6: IT | D6: Systems Analyst | E6: 220
A7: EMP-006 | B7: Farida Younes | C7: Operations | D7: Operations Coordinator | E7: 180
A8: EMP-007 | B8: Reem Gaber | C8: Operations | D8: Operations Coordinator | E8: 180
A9: EMP-008 | B9: Sherif Hosny | C9: Operations | D9: Logistics Planner | E9: 200
A10: EMP-009 | B10: Farida Zaki | C10: Operations | D10: Operations Coordinator | E10: 200
A11: EMP-010 | B11: Yasmin Zaki | C11: Operations | D11: Logistics Planner | E11: 220
A12: EMP-011 | B12: Khaled Naguib | C12: Finance | D12: Budget Controller | E12: 250
A13: EMP-012 | B13: Khaled Younes | C13: Finance | D13: Accountant | E13: 280
... A28: EMP-027 | B28: Salma Fouad | C28: Quality Assurance | D28: QA Engineer | E28: 200

Sheet tbl_Tasks_Clean.
A1: Task_ID | B1: Project_ID | C1: Project_Name | D1: Task_Name | E1: Department | F1: Assigned_To | G1: Priority | H1: Status | I1: Planned_Cost | J1: Actual_Cost | K1: Start_Date | L1: Planned_End_Date | M1: Actual_End_Date | N1: Planned_Duration_Days | O1: Delay_Days | P1: Client | Q1: Project_Manager | R1: Budget | S1: Employee_Department | T1: Hourly_Rate | U1: Cost_Variance | V1: Cost_Variance_% | W1: On_Flag | X1: Task_Age_Category | Y1: Manager_Lookup | Z1: Delay_Description
A2: TSK-0085 | B2: PRJ-004 | C2: Warehouse Automation | D2: Audit marketing collateral | E2: Finance | F2: Farida Hosny | G2: Medium | H2: Delayed | I2: 1500 | J2: 1396 | K2: 45478 | L2: 45506 | M2: 45513 | N2: 28 | O2: 7 | P2: Cairo Financial Services | Q2: Laila Samir | R2: 75000 | S2: HR | T2: 150 | U2: =tbl_Tasks_Clean[[#This Row],[Actual_Cost]]-tbl_Tasks_Clean[[#This Row],[Planned_Cost]] -> -104 | V2: =IFERROR(tbl_Tasks_Clean[[#This Row],[Cost_Variance]]/tbl_Tasks_Clean[[#This Row],[Planned_Cost]],0) -> -0.069333333 | W2: =IF(AND(tbl_Tasks_Clean[[#This Row],[Status]]="Completed",tbl_Tasks_Clean[[#This Row],[Delay_Days]]<=0),"On Time",IF(AND(tbl_Tasks_Clean[[#This Row],[Status]]="Completed",tbl_Tasks_Clean[[#This Row],[Delay_Days]]>0),"Late","N/A")) -> N/A | X2: {=_xlfn.IFS(tbl_Tasks_Clean[[#This Row],[Planned_Duration_Days]]<=7,"Short (<=7 days)",tbl_Tasks_Clean[[#This Row],[Planned_Duration_Days]]<=20,"Medium (8-20 days)",TRUE,"Long (>20 days)")} -> Long (>20 days) | Y2: =INDEX(Projects!$D:$D,MATCH(tbl_Tasks_Clean[[#This Row],[Project_ID]],Projects!$A:$A,0)) -> Laila Samir | Z2: =IF(tbl_Tasks_Clean[[#This Row],[Delay_Days]]>0,"Delayed by "&TEXT(tbl_Tasks_Clean[[#This Row],[Delay_Days]],"0")&" days",IF(tbl_Tasks_Clean[[#This Row],[Delay_Days]]<0,"Early by "&TEXT(-tbl_Tasks_Clean[[#This Row],[Delay_Days]],"0")&" days","On schedule")) -> Delayed by 7 days
A3: TSK-0014 | B3: PRJ-001 | C3: Website Redesign | D3: Deploy inventory system | E3: Operations | F3: Farida Hosny | G3: Medium | H3: In Progress | I3: 1500 | J3: 618 | K3: 45518 | L3: 45542 | N3: 24 | O3: 0 | P3: Nile Corp | Q3: Mona Farid | R3: 75000 | S3: HR | T3: 150 | U3: =tbl_Tasks_Clean[[#This Row],[Actual_Cost]]-tbl_Tasks_Clean[[#This Row],[Planned_Cost]] -> -882 | V3: =IFERROR(tbl_Tasks_Clean[[#This Row],[Cost_Variance]]/tbl_Tasks_Clean[[#This Row],[Planned_Cost]],0) -> -0.588 | W3: =IF(AND(tbl_Tasks_Clean[[#This Row],[Status]]="Completed",tbl_Tasks_Clean[[#This Row],[Delay_Days]]<=0),"On Time",IF(AND(tbl_Tasks_Clean[[#This Row],[Status]]="Completed",tbl_Tasks_Clean[[#This Row],[Delay_Days]]>0),"Late","N/A")) -> N/A | X3: {=_xlfn.IFS(tbl_Tasks_Clean[[#This Row],[Planned_Duration_Days]]<=7,"Short (<=7 days)",tbl_Tasks_Clean[[#This Row],[Planned_Duration_Days]]<=20,"Medium (8-20 days)",TRUE,"Long (>20 days)")} -> Long (>20 days) | Y3: =INDEX(Projects!$D:$D,MATCH(tbl_Tasks_Clean[[#This Row],[Project_ID]],Projects!$A:$A,0)) -> Mona Farid | Z3: =IF(tbl_Tasks_Clean[[#This Row],[Delay_Days]]>0,"Delayed by "&TEXT(tbl_Tasks_Clean[[#This Row],[Delay_Days]],"0")&" days",IF(tbl_Tasks_Clean[[#This Row],[Delay_Days]]<0,"Early by "&TEXT(-tbl_Tasks_Clean[[#This Row],[Delay_Days]],"0")&" days","On schedule")) -> On schedule
A4: TSK-0053 | B4: PRJ-003 | C4: Mobile App Launch | D4: Migrate API integration | E4: IT | F4: Farida Hosny | G4: Medium | H4: Completed | I4: 4000 | J4: 5187 | K4: 45450 | L4: 45473 | M4: 45470 | N4: 23 | O4: -3 | P4: Alexandria Logistics | Q4: Ahmed Nabil | R4: 100000 | S4: HR | T4: 150 | U4: =tbl_Tasks_Clean[[#This Row],[Actual_Cost]]-tbl_Tasks_Clean[[#This Row],[Planned_Cost]] -> 1187 | V4: =IFERROR(tbl_Tasks_Clean[[#This Row],[Cost_Variance]]/tbl_Tasks_Clean[[#This Row],[Planned_Cost]],0) -> 0.29675 | W4: =IF(AND(tbl_Tasks_Clean[[#This Row],[Status]]="Completed",tbl_Tasks_Clean[[#This Row],[Delay_Days]]<=0),"On Time",IF(AND(tbl_Tasks_Clean[[#This Row],[Status]]="Completed",tbl_Tasks_Clean[[#This Row],[Delay_Days]]>0),"Late","N/A")) -> On Time | X4: {=_xlfn.IFS(tbl_Tasks_Clean[[#This Row],[Planned_Duration_Days]]<=7,"Short (<=7 days)",tbl_Tasks_Clean[[#This Row],[Planned_Duration_Days]]<=20,"Medium (8-20 days)",TRUE,"Long (>20 days)")} -> Long (>20 days) | Y4: =INDEX(Projects!$D:$D,MATCH(tbl_Tasks_Clean[[#This Row],[Project_ID]],Projects!$A:$A,0)) -> Ahmed Nabil | Z4: =IF(tbl_Tasks_Clean[[#This Row],[Delay_Days]]>0,"Delayed by "&TEXT(tbl_Tasks_Clean[[#This Row],[Delay_Days]],"0")&" days",IF(tbl_Tasks_Clean[[#This Row],[Delay_Days]]<0,"Early by "&TEXT(-tbl_Tasks_Clean[[#This Row],[Delay_Days]],"0")&" days","On schedule")) -> Early by 3 days
A5: TSK-0082 | B5: PRJ-004 | C5: Warehouse Automation | D5: Audit budget report | E5: Marketing | F5: Yasmin Younes | G5: High | H5: Done | I5: 0 | J5: 6098 | K5: 45594 | L5: 45599 | M5: 45598 | N5: 5 | O5: -1 | P5: Cairo Financial Services | Q5: Laila Samir | R5: 75000 | S5: IT | T5: 220 | U5: =tbl_Tasks_Clean[[#This Row],[Actual_Cost]]-tbl_Tasks_Clean[[#This Row],[Planned_Cost]] -> 6098 | V5: =IFERROR(tbl_Tasks_Clean[[#This Row],[Cost_Variance]]/tbl_Tasks_Clean[[#This Row],[Planned_Cost]],0) -> 0 | W5: =IF(AND(tbl_Tasks_Clean[[#This Row],[Status]]="Completed",tbl_Tasks_Clean[[#This Row],[Delay_Days]]<=0),"On Time",IF(AND(tbl_Tasks_Clean[[#This Row],[Status]]="Completed",tbl_Tasks_Clean[[#This Row],[Delay_Days]]>0),"Late","N/A")) -> N/A | X5: {=_xlfn.IFS(tbl_Tasks_Clean[[#This Row],[Planned_Duration_Days]]<=7,"Short (<=7 days)",tbl_Tasks_Clean[[#This Row],[Planned_Duration_Days]]<=20,"Medium (8-20 days)",TRUE,"Long (>20 days)")} -> Short (<=7 days) | Y5: =INDEX(Projects!$D:$D,MATCH(tbl_Tasks_Clean[[#This Row],[Project_ID]],Projects!$A:$A,0)) -> Laila Samir | Z5: =IF(tbl_Tasks_Clean[[#This Row],[Delay_Days]]>0,"Delayed by "&TEXT(tbl_Tasks_Clean[[#This Row],[Delay_Days]],"0")&" days",IF(tbl_Tasks_Clean[[#This Row],[Delay_Days]]<0,"Early by "&TEXT(-tbl_Tasks_Clean[[#This Row],[Delay_Days]],"0")&" days","On schedule")) -> Early by 1 days
A6: TSK-0276 | B6: PRJ-014 | C6: Retail Store Opening | D6: Develop backup procedure | E6: Operations | F6: Noor Naguib | G6: High | H6: In Progress | I6: 4000 | J6: 1731 | K6: 45435 | L6: 45463 | N6: 28 | O6: 0 | P6: Orbit Media | Q6: Ahmed Nabil | R6: 300000 | S6: Marketing | T6: 280 | U6: =tbl_Tasks_Clean[[#This Row],[Actual_Cost]]-tbl_Tasks_Clean[[#This Row],[Planned_Cost]] -> -2269 | V6: =IFERROR(tbl_Tasks_Clean[[#This Row],[Cost_Variance]]/tbl_Tasks_Clean[[#This Row],[Planned_Cost]],0) -> -0.56725 | W6: =IF(AND(tbl_Tasks_Clean[[#This Row],[Status]]="Completed",tbl_Tasks_Clean[[#This Row],[Delay_Days]]<=0),"On Time",IF(AND(tbl_Tasks_Clean[[#This Row],[Status]]="Completed",tbl_Tasks_Clean[[#This Row],[Delay_Days]]>0),"Late","N/A")) -> N/A | X6: {=_xlfn.IFS(tbl_Tasks_Clean[[#This Row],[Planned_Duration_Days]]<=7,"Short (<=7 days)",tbl_Tasks_Clean[[#This Row],[Planned_Duration_Days]]<=20,"Medium (8-20 days)",TRUE,"Long (>20 days)")} -> Long (>20 days) | Y6: =INDEX(Projects!$D:$D,MATCH(tbl_Tasks_Clean[[#This Row],[Project_ID]],Projects!$A:$A,0)) -> Ahmed Nabil | Z6: =IF(tbl_Tasks_Clean[[#This Row],[Delay_Days]]>0,"Delayed by "&TEXT(tbl_Tasks_Clean[[#This Row],[Delay_Days]],"0")&" days",IF(tbl_Tasks_Clean[[#This Row],[Delay_Days]]<0,"Early by "&TEXT(-tbl_Tasks_Clean[[#This Row],[Delay_Days]],"0")&" days","On schedule")) -> On schedule
A7: TSK-0104 | B7: PRJ-005 | C7: Customer Portal Upgrade | D7: Install budget report | E7: Finance | F7: Noor Naguib | G7: Low | H7: Completed | I7: 2000 | J7: 2594 | O7: 0 | P7: Horizon Manufacturing | Q7: Ahmed Nabil | R7: 50000 | S7: Marketing | T7: 280 | U7: =tbl_Tasks_Clean[[#This Row],[Actual_Cost]]-tbl_Tasks_Clean[[#This Row],[Planned_Cost]] -> 594 | V7: =IFERROR(tbl_Tasks_Clean[[#This Row],[Cost_Variance]]/tbl_Tasks_Clean[[#This Row],[Planned_Cost]],0) -> 0.297 | W7: =IF(AND(tbl_Tasks_Clean[[#This Row],[Status]]="Completed",tbl_Tasks_Clean[[#This Row],[Delay_Days]]<=0),"On Time",IF(AND(tbl_Tasks_Clean[[#This Row],[Status]]="Completed",tbl_Tasks_Clean[[#This Row],[Delay_Days]]>0),"Late","N/A")) -> On Time | X7: {=_xlfn.IFS(tbl_Tasks_Clean[[#This Row],[Planned_Duration_Days]]<=7,"Short (<=7 days)",tbl_Tasks_Clean[[#This Row],[Planned_Duration_Days]]<=20,"Medium (8-20 days)",TRUE,"Long (>20 days)")} -> Short (<=7 days) | Y7: =INDEX(Projects!$D:$D,MATCH(tbl_Tasks_Clean[[#This Row],[Project_ID]],Projects!$A:$A,0)) -> Ahmed Nabil | Z7: =IF(tbl_Tasks_Clean[[#This Row],[Delay_Days]]>0,"Delayed by "&TEXT(tbl_Tasks_Clean[[#This Row],[Delay_Days]],"0")&" days",IF(tbl_Tasks_Clean[[#This Row],[Delay_Days]]<0,"Early by "&TEXT(-tbl_Tasks_Clean[[#This Row],[Delay_Days]],"0")&" days","On schedule")) -> On schedule
A8: TSK-0192 | B8: PRJ-010 | C8: Product Line Expansion | D8: Analyze security policy | E8: IT | F8: Noor Naguib | G8: Medium | H8: Not Started | I8: 8000 | J8: 0 | K8: 45462 | L8: 45467 | N8: 5 | O8: 0 | P8: Internal | Q8: Sara Hassan | R8: 150000 | S8: Marketing | T8: 280 | U8: =tbl_Tasks_Clean[[#This Row],[Actual_Cost]]-tbl_Tasks_Clean[[#This Row],[Planned_Cost]] -> -8000 | V8: =IFERROR(tbl_Tasks_Clean[[#This Row],[Cost_Variance]]/tbl_Tasks_Clean[[#This Row],[Planned_Cost]],0) -> -1 | W8: =IF(AND(tbl_Tasks_Clean[[#This Row],[Status]]="Completed",tbl_Tasks_Clean[[#This Row],[Delay_Days]]<=0),"On Time",IF(AND(tbl_Tasks_Clean[[#This Row],[Status]]="Completed",tbl_Tasks_Clean[[#This Row],[Delay_Days]]>0),"Late","N/A")) -> N/A | X8: {=_xlfn.IFS(tbl_Tasks_Clean[[#This Row],[Planned_Duration_Days]]<=7,"Short (<=7 days)",tbl_Tasks_Clean[[#This Row],[Planned_Duration_Days]]<=20,"Medium (8-20 days)",TRUE,"Long (>20 days)")} -> Short (<=7 days) | Y8: =INDEX(Projects!$D:$D,MATCH(tbl_Tasks_Clean[[#This Row],[Project_ID]],Projects!$A:$A,0)) -> Sara Hassan | Z8: =IF(tbl_Tasks_Clean[[#This Row],[Delay_Days]]>0,"Delayed by "&TEXT(tbl_Tasks_Clean[[#This Row],[Delay_Days]],"0")&" days",IF(tbl_Tasks_Clean[[#This Row],[Delay_Days]]<0,"Early by "&TEXT(-tbl_Tasks_Clean[[#This Row],[Delay_Days]],"0")&" days","On schedule")) -> On schedule
A9: TSK-0245 | B9: PRJ-012 | C9: Cloud Migration | D9: Test marketing collateral | E9: Marketing | F9: Noor Naguib | G9: Low | H9: Completed | I9: 1500 | J9: 1982 | K9: 45348 | L9: 45366 | M9: 45366 | N9: 18 | O9: 0 | P9: Red Sea Tourism | Q9: Ahmed Nabil | R9: 250000 | S9: Marketing | T9: 280 | U9: =tbl_Tasks_Clean[[#This Row],[Actual_Cost]]-tbl_Tasks_Clean[[#This Row],[Planned_Cost]] -> 482 | V9: =IFERROR(tbl_Tasks_Clean[[#This Row],[Cost_Variance]]/tbl_Tasks_Clean[[#This Row],[Planned_Cost]],0) -> 0.32133333 | W9: =IF(AND(tbl_Tasks_Clean[[#This Row],[Status]]="Completed",tbl_Tasks_Clean[[#This Row],[Delay_Days]]<=0),"On Time",IF(AND(tbl_Tasks_Clean[[#This Row],[Status]]="Completed",tbl_Tasks_Clean[[#This Row],[Delay_Days]]>0),"Late","N/A")) -> On Time | X9: {=_xlfn.IFS(tbl_Tasks_Clean[[#This Row],[Planned_Duration_Days]]<=7,"Short (<=7 days)",tbl_Tasks_Clean[[#This Row],[Planned_Duration_Days]]<=20,"Medium (8-20 days)",TRUE,"Long (>20 days)")} -> Medium (8-20 days) | Y9: =INDEX(Projects!$D:$D,MATCH(tbl_Tasks_Clean[[#This Row],[Project_ID]],Projects!$A:$A,0)) -> Ahmed Nabil | Z9: =IF(tbl_Tasks_Clean[[#This Row],[Delay_Days]]>0,"Delayed by "&TEXT(tbl_Tasks_Clean[[#This Row],[Delay_Days]],"0")&" days",IF(tbl_Tasks_Clean[[#This Row],[Delay_Days]]<0,"Early by "&TEXT(-tbl_Tasks_Clean[[#This Row],[Delay_Days]],"0")&" days","On schedule")) -> On schedule
A10: TSK-0153 | B10: PRJ-008 | C10: Office Relocation | D10: Audit inventory system | F10: Hassan Fouad | G10: Medium | H10: Ongoing | I10: 10000 | J10: 5964 | K10: 45395 | L10: 45419 | N10: 24 | O10: 0 | P10: Pharos Holdings | Q10: Nourhan Tarek | R10: 300000 | S10: IT | T10: 280 | U10: =tbl_Tasks_Clean[[#This Row],[Actual_Cost]]-tbl_Tasks_Clean[[#This Row],[Planned_Cost]] -> -4036 | V10: =IFERROR(tbl_Tasks_Clean[[#This Row],[Cost_Variance]]/tbl_Tasks_Clean[[#This Row],[Planned_Cost]],0) -> -0.4036 | W10: =IF(AND(tbl_Tasks_Clean[[#This Row],[Status]]="Completed",tbl_Tasks_Clean[[#This Row],[Delay_Days]]<=0),"On Time",IF(AND(tbl_Tasks_Clean[[#This Row],[Status]]="Completed",tbl_Tasks_Clean[[#This Row],[Delay_Days]]>0),"Late","N/A")) -> N/A | X10: {=_xlfn.IFS(tbl_Tasks_Clean[[#This Row],[Planned_Duration_Days]]<=7,"Short (<=7 days)",tbl_Tasks_Clean[[#This Row],[Planned_Duration_Days]]<=20,"Medium (8-20 days)",TRUE,"Long (>20 days)")} -> Long (>20 days) | Y10: =INDEX(Projects!$D:$D,MATCH(tbl_Tasks_Clean[[#This Row],[Project_ID]],Projects!$A:$A,0)) -> Nourhan Tarek | Z10: =IF(tbl_Tasks_Clean[[#This Row],[Delay_Days]]>0,"Delayed by "&TEXT(tbl_Tasks_Clean[[#This Row],[Delay_Days]],"0")&" days",IF(tbl_Tasks_Clean[[#This Row],[Delay_Days]]<0,"Early by "&TEXT(-tbl_Tasks_Clean[[#This Row],[Delay_Days]],"0")&" days","On schedule")) -> On schedule
A11: TSK-0288 | B11: PRJ-014 | C11: Retail Store Opening | D11: Optimize customer feedback survey | E11: IT | F11: Salma Fouad | G11: Low | H11: Completed | I11: 1000 | J11: 1263 | O11: 0 | P11: Orbit Media | Q11: Ahmed Nabil | R11: 300000 | S11: Quality Assurance | T11: 200 | U11: =tbl_Tasks_Clean[[#This Row],[Actual_Cost]]-tbl_Tasks_Clean[[#This Row],[Planned_Cost]] -> 263 | V11: =IFERROR(tbl_Tasks_Clean[[#This Row],[Cost_Variance]]/tbl_Tasks_Clean[[#This Row],[Planned_Cost]],0) -> 0.263 | W11: =IF(AND(tbl_Tasks_Clean[[#This Row],[Status]]="Completed",tbl_Tasks_Clean[[#This Row],[Delay_Days]]<=0),"On Time",IF(AND(tbl_Tasks_Clean[[#This Row],[Status]]="Completed",tbl_Tasks_Clean[[#This Row],[Delay_Days]]>0),"Late","N/A")) -> On Time | X11: {=_xlfn.IFS(tbl_Tasks_Clean[[#This Row],[Planned_Duration_Days]]<=7,"Short (<=7 days)",tbl_Tasks_Clean[[#This Row],[Planned_Duration_Days]]<=20,"Medium (8-20 days)",TRUE,"Long (>20 days)")} -> Short (<=7 days) | Y11: =INDEX(Projects!$D:$D,MATCH(tbl_Tasks_Clean[[#This Row],[Project_ID]],Projects!$A:$A,0)) -> Ahmed Nabil | Z11: =IF(tbl_Tasks_Clean[[#This Row],[Delay_Days]]>0,"Delayed by "&TEXT(tbl_Tasks_Clean[[#This Row],[Delay_Days]],"0")&" days",IF(tbl_Tasks_Clean[[#This Row],[Delay_Days]]<0,"Early by "&TEXT(-tbl_Tasks_Clean[[#This Row],[Delay_Days]],"0")&" days","On schedule")) -> On schedule
A12: TSK-0204 | B12: PRJ-010 | C12: Product Line Expansion | D12: Document warehouse layout | E12: IT | F12: Salma Fouad | G12: High | H12: Done | I12: 2500 | J12: 2216 | K12: 45404 | L12: 45414 | M12: 45416 | N12: 10 | O12: 2 | P12: Internal | Q12: Sara Hassan | R12: 150000 | S12: Quality Assurance | T12: 200 | U12: =tbl_Tasks_Clean[[#This Row],[Actual_Cost]]-tbl_Tasks_Clean[[#This Row],[Planned_Cost]] -> -284 | V12: =IFERROR(tbl_Tasks_Clean[[#This Row],[Cost_Variance]]/tbl_Tasks_Clean[[#This Row],[Planned_Cost]],0) -> -0.1136 | W12: =IF(AND(tbl_Tasks_Clean[[#This Row],[Status]]="Completed",tbl_Tasks_Clean[[#This Row],[Delay_Days]]<=0),"On Time",IF(AND(tbl_Tasks_Clean[[#This Row],[Status]]="Completed",tbl_Tasks_Clean[[#This Row],[Delay_Days]]>0),"Late","N/A")) -> N/A | X12: {=_xlfn.IFS(tbl_Tasks_Clean[[#This Row],[Planned_Duration_Days]]<=7,"Short (<=7 days)",tbl_Tasks_Clean[[#This Row],[Planned_Duration_Days]]<=20,"Medium (8-20 days)",TRUE,"Long (>20 days)")} -> Medium (8-20 days) | Y12: =INDEX(Projects!$D:$D,MATCH(tbl_Tasks_Clean[[#This Row],[Project_ID]],Projects!$A:$A,0)) -> Sara Hassan | Z12: =IF(tbl_Tasks_Clean[[#This Row],[Delay_Days]]>0,"Delayed by "&TEXT(tbl_Tasks_Clean[[#This Row],[Delay_Days]],"0")&" days",IF(tbl_Tasks_Clean[[#This Row],[Delay_Days]]<0,"Early by "&TEXT(-tbl_Tasks_Clean[[#This Row],[Delay_Days]],"0")&" days","On schedule")) -> Delayed by 2 days
A13: TSK-0211 | B13: PRJ-011 | C13: HR System Implementation | D13: Document training material | E13: IT | F13: Tarek Abdelrahman | G13: High | H13: In Progress | I13: 4000 | J13: 2110 | K13: 45473 | L13: 45488 | N13: 15 | O13: 0 | P13: Giza Health Systems | Q13: Ahmed Nabil | R13: 200000 | S13: IT | T13: 180 | U13: =tbl_Tasks_Clean[[#This Row],[Actual_Cost]]-tbl_Tasks_Clean[[#This Row],[Planned_Cost]] -> -1890 | V13: =IFERROR(tbl_Tasks_Clean[[#This Row],[Cost_Variance]]/tbl_Tasks_Clean[[#This Row],[Planned_Cost]],0) -> -0.4725 | W13: =IF(AND(tbl_Tasks_Clean[[#This Row],[Status]]="Completed",tbl_Tasks_Clean[[#This Row],[Delay_Days]]<=0),"On Time",IF(AND(tbl_Tasks_Clean[[#This Row],[Status]]="Completed",tbl_Tasks_Clean[[#This Row],[Delay_Days]]>0),"Late","N/A")) -> N/A | X13: {=_xlfn.IFS(tbl_Tasks_Clean[[#This Row],[Planned_Duration_Days]]<=7,"Short (<=7 days)",tbl_Tasks_Clean[[#This Row],[Planned_Duration_Days]]<=20,"Medium (8-20 days)",TRUE,"Long (>20 days)")} -> Medium (8-20 days) | Y13: =INDEX(Projects!$D:$D,MATCH(tbl_Tasks_Clean[[#This Row],[Project_ID]],Projects!$A:$A,0)) -> Ahmed Nabil | Z13: =IF(tbl_Tasks_Clean[[#This Row],[Delay_Days]]>0,"Delayed by "&TEXT(tbl_Tasks_Clean[[#This Row],[Delay_Days]],"0")&" days",IF(tbl_Tasks_Clean[[#This Row],[Delay_Days]]<0,"Early by "&TEXT(-tbl_Tasks_Clean[[#This Row],[Delay_Days]],"0")&" days","On schedule")) -> On schedule
A14: TSK-0038 | B14: PRJ-002 | C14: ERP System Rollout | D14: Audit API integration | E14: Procurement | F14: Tarek Abdelrahman | G14: High | H14: Not Started | I14: 6000 | J14: 0 | K14: 45513 | L14: 45536 | N14: 23 | O14: 0 | P14: Delta Retail Group | Q14: Youssef Adel | R14: 150000 | S14: IT | T14: 180 | U14: =tbl_Tasks_Clean[[#This Row],[Actual_Cost]]-tbl_Tasks_Clean[[#This Row],[Planned_Cost]] -> -6000 | V14: =IFERROR(tbl_Tasks_Clean[[#This Row],[Cost_Variance]]/tbl_Tasks_Clean[[#This Row],[Planned_Cost]],0) -> -1 | W14: =IF(AND(tbl_Tasks_Clean[[#This Row],[Status]]="Completed",tbl_Tasks_Clean[[#This Row],[Delay_Days]]<=0),"On Time",IF(AND(tbl_Tasks_Clean[[#This Row],[Status]]="Completed",tbl_Tasks_Clean[[#This Row],[Delay_Days]]>0),"Late","N/A")) -> N/A | X14: {=_xlfn.IFS(tbl_Tasks_Clean[[#This Row],[Planned_Duration_Days]]<=7,"Short (<=7 days)",tbl_Tasks_Clean[[#This Row],[Planned_Duration_Days]]<=20,"Medium (8-20 days)",TRUE,"Long (>20 days)")} -> Long (>20 days) | Y14: =INDEX(Projects!$D:$D,MATCH(tbl_Tasks_Clean[[#This Row],[Project_ID]],Projects!$A:$A,0)) -> Youssef Adel | Z14: =IF(tbl_Tasks_Clean[[#This Row],[Delay_Days]]>0,"Delayed by "&TEXT(tbl_Tasks_Clean[[#This Row],[Delay_Days]],"0")&" days",IF(tbl_Tasks_Clean[[#This Row],[Delay_Days]]<0,"Early by "&TEXT(-tbl_Tasks_Clean[[#This Row],[Delay_Days]],"0")&" days","On schedule")) -> On schedule
A15: TSK-0216 | B15: PRJ-011 | C15: HR System Implementation | D15: Procure warehouse layout | E15: Marketing | F15: Khaled Younes | G15: Low | H15: In Progress | I15: 1500 | J15: 377 | K15: 45385 | L15: 45412 | N15: 27 | O15: 0 | P15: Giza Health Systems | Q15: Ahmed Nabil | R15: 200000 | S15: Finance | T15: 280 | U15: =tbl_Tasks_Clean[[#This Row],[Actual_Cost]]-tbl_Tasks_Clean[[#This Row],[Planned_Cost]] -> -1123 | V15: =IFERROR(tbl_Tasks_Clean[[#This Row],[Cost_Variance]]/tbl_Tasks_Clean[[#This Row],[Planned_Cost]],0) -> -0.74866667 | W15: =IF(AND(tbl_Tasks_Clean[[#This Row],[Status]]="Completed",tbl_Tasks_Clean[[#This Row],[Delay_Days]]<=0),"On Time",IF(AND(tbl_Tasks_Clean[[#This Row],[Status]]="Completed",tbl_Tasks_Clean[[#This Row],[Delay_Days]]>0),"Late","N/A")) -> N/A | X15: {=_xlfn.IFS(tbl_Tasks_Clean[[#This Row],[Planned_Duration_Days]]<=7,"Short (<=7 days)",tbl_Tasks_Clean[[#This Row],[Planned_Duration_Days]]<=20,"Medium (8-20 days)",TRUE,"Long (>20 days)")} -> Long (>20 days) | Y15: =INDEX(Projects!$D:$D,MATCH(tbl_Tasks_Clean[[#This Row],[Project_ID]],Projects!$A:$A,0)) -> Ahmed Nabil | Z15: =IF(tbl_Tasks_Clean[[#This Row],[Delay_Days]]>0,"Delayed by "&TEXT(tbl_Tasks_Clean[[#This Row],[Delay_Days]],"0")&" days",IF(tbl_Tasks_Clean[[#This Row],[Delay_Days]]<0,"Early by "&TEXT(-tbl_Tasks_Clean[[#This Row],[Delay_Days]],"0")&" days","On schedule")) -> On schedule
A16: TSK-0093 | B16: PRJ-005 | C16: Customer Portal Upgrade | D16: Procure vendor contract | E16: Marketing | F16: Dina Zaki | G16: Medium | H16: Completed | I16: 0 | J16: 2553 | K16: 45301 | L16: 45306 | M16: 45303 | N16: 5 | O16: -3 | P16: Horizon Manufacturing | Q16: Ahmed Nabil | R16: 50000 | S16: IT | T16: 220 | U16: =tbl_Tasks_Clean[[#This Row],[Actual_Cost]]-tbl_Tasks_Clean[[#This Row],[Planned_Cost]] -> 2553 | V16: =IFERROR(tbl_Tasks_Clean[[#This Row],[Cost_Variance]]/tbl_Tasks_Clean[[#This Row],[Planned_Cost]],0) -> 0 | W16: =IF(AND(tbl_Tasks_Clean[[#This Row],[Status]]="Completed",tbl_Tasks_Clean[[#This Row],[Delay_Days]]<=0),"On Time",IF(AND(tbl_Tasks_Clean[[#This Row],[Status]]="Completed",tbl_Tasks_Clean[[#This Row],[Delay_Days]]>0),"Late","N/A")) -> On Time | X16: {=_xlfn.IFS(tbl_Tasks_Clean[[#This Row],[Planned_Duration_Days]]<=7,"Short (<=7 days)",tbl_Tasks_Clean[[#This Row],[Planned_Duration_Days]]<=20,"Medium (8-20 days)",TRUE,"Long (>20 days)")} -> Short (<=7 days) | Y16: =INDEX(Projects!$D:$D,MATCH(tbl_Tasks_Clean[[#This Row],[Project_ID]],Projects!$A:$A,0)) -> Ahmed Nabil | Z16: =IF(tbl_Tasks_Clean[[#This Row],[Delay_Days]]>0,"Delayed by "&TEXT(tbl_Tasks_Clean[[#This Row],[Delay_Days]],"0")&" days",IF(tbl_Tasks_Clean[[#This Row],[Delay_Days]]<0,"Early by "&TEXT(-tbl_Tasks_Clean[[#This Row],[Delay_Days]],"0")&" days","On schedule")) -> Early by 3 days
A17: TSK-0212 | B17: PRJ-011 | C17: HR System Implementation | D17: Test backup procedure | E17: IT | F17: Farida Younes | G17: High | H17: Not Started | I17: 5000 | J17: 0 | K17: 45434 | L17: 45442 | N17: 8 | O17: 0 | P17: Giza Health Systems | Q17: Ahmed Nabil | R17: 200000 | S17: Operations | T17: 180 | U17: =tbl_Tasks_Clean[[#This Row],[Actual_Cost]]-tbl_Tasks_Clean[[#This Row],[Planned_Cost]] -> -5000 | V17: =IFERROR(tbl_Tasks_Clean[[#This Row],[Cost_Variance]]/tbl_Tasks_Clean[[#This Row],[Planned_Cost]],0) -> -1 | W17: =IF(AND(tbl_Tasks_Clean[[#This Row],[Status]]="Completed",tbl_Tasks_Clean[[#This Row],[Delay_Days]]<=0),"On Time",IF(AND(tbl_Tasks_Clean[[#This Row],[Status]]="Completed",tbl_Tasks_Clean[[#This Row],[Delay_Days]]>0),"Late","N/A")) -> N/A | X17: {=_xlfn.IFS(tbl_Tasks_Clean[[#This Row],[Planned_Duration_Days]]<=7,"Short (<=7 days)",tbl_Tasks_Clean[[#This Row],[Planned_Duration_Days]]<=20,"Medium (8-20 days)",TRUE,"Long (>20 days)")} -> Medium (8-20 days) | Y17: =INDEX(Projects!$D:$D,MATCH(tbl_Tasks_Clean[[#This Row],[Project_ID]],Projects!$A:$A,0)) -> Ahmed Nabil | Z17: =IF(tbl_Tasks_Clean[[#This Row],[Delay_Days]]>0,"Delayed by "&TEXT(tbl_Tasks_Clean[[#This Row],[Delay_Days]],"0")&" days",IF(tbl_Tasks_Clean[[#This Row],[Delay_Days]]<0,"Early by "&TEXT(-tbl_Tasks_Clean[[#This Row],[Delay_Days]],"0")&" days","On schedule")) -> On schedule
A18: TSK-0058 | B18: PRJ-003 | C18: Mobile App Launch | D18: Audit inventory system | F18: Tarek Shawky | G18: Medium | H18: Not Started | I18: 1000 | J18: 0 | K18: 45493 | L18: 45523 | N18: 30 | O18: 0 | P18: Alexandria Logistics | Q18: Ahmed Nabil | R18: 100000 | S18: Procurement | T18: 150 | U18: =tbl_Tasks_Clean[[#This Row],[Actual_Cost]]-tbl_Tasks_Clean[[#This Row],[Planned_Cost]] -> -1000 | V18: =IFERROR(tbl_Tasks_Clean[[#This Row],[Cost_Variance]]/tbl_Tasks_Clean[[#This Row],[Planned_Cost]],0) -> -1 | W18: =IF(AND(tbl_Tasks_Clean[[#This Row],[Status]]="Completed",tbl_Tasks_Clean[[#This Row],[Delay_Days]]<=0),"On Time",IF(AND(tbl_Tasks_Clean[[#This Row],[Status]]="Completed",tbl_Tasks_Clean[[#This Row],[Delay_Days]]>0),"Late","N/A")) -> N/A | X18: {=_xlfn.IFS(tbl_Tasks_Clean[[#This Row],[Planned_Duration_Days]]<=7,"Short (<=7 days)",tbl_Tasks_Clean[[#This Row],[Planned_Duration_Days]]<=20,"Medium (8-20 days)",TRUE,"Long (>20 days)")} -> Long (>20 days) | Y18: =INDEX(Projects!$D:$D,MATCH(tbl_Tasks_Clean[[#This Row],[Project_ID]],Projects!$A:$A,0)) -> Ahmed Nabil | Z18: =IF(tbl_Tasks_Clean[[#This Row],[Delay_Days]]>0,"Delayed by "&TEXT(tbl_Tasks_Clean[[#This Row],[Delay_Days]],"0")&" days",IF(tbl_Tasks_Clean[[#This Row],[Delay_Days]]<0,"Early by "&TEXT(-tbl_Tasks_Clean[[#This Row],[Delay_Days]],"0")&" days","On schedule")) -> On schedule
A19: TSK-0213 | B19: PRJ-011 | C19: HR System Implementation | D19: Train users on hardware setup | E19: Marketing | F19: Reem Gaber | G19: Low | H19: In Progress | I19: 1500 | J19: 598 | K19: 45387 | L19: 45391 | N19: 4 | O19: 0 | P19: Giza Health Systems | Q19: Ahmed Nabil | R19: 200000 | S19: Operations | T19: 180 | U19: =tbl_Tasks_Clean[[#This Row],[Actual_Cost]]-tbl_Tasks_Clean[[#This Row],[Planned_Cost]] -> -902 | V19: =IFERROR(tbl_Tasks_Clean[[#This Row],[Cost_Variance]]/tbl_Tasks_Clean[[#This Row],[Planned_Cost]],0) -> -0.60133333 | W19: =IF(AND(tbl_Tasks_Clean[[#This Row],[Status]]="Completed",tbl_Tasks_Clean[[#This Row],[Delay_Days]]<=0),"On Time",IF(AND(tbl_Tasks_Clean[[#This Row],[Status]]="Completed",tbl_Tasks_Clean[[#This Row],[Delay_Days]]>0),"Late","N/A")) -> N/A | X19: {=_xlfn.IFS(tbl_Tasks_Clean[[#This Row],[Planned_Duration_Days]]<=7,"Short (<=7 days)",tbl_Tasks_Clean[[#This Row],[Planned_Duration_Days]]<=20,"Medium (8-20 days)",TRUE,"Long (>20 days)")} -> Short (<=7 days) | Y19: =INDEX(Projects!$D:$D,MATCH(tbl_Tasks_Clean[[#This Row],[Project_ID]],Projects!$A:$A,0)) -> Ahmed Nabil | Z19: =IF(tbl_Tasks_Clean[[#This Row],[Delay_Days]]>0,"Delayed by "&TEXT(tbl_Tasks_Clean[[#This Row],[Delay_Days]],"0")&" days",IF(tbl_Tasks_Clean[[#This Row],[Delay_Days]]<0,"Early by "&TEXT(-tbl_Tasks_Clean[[#This Row],[Delay_Days]],"0")&" days","On schedule")) -> On schedule
A20: TSK-0024 | B20: PRJ-002 | C20: ERP System Rollout | D20: Migrate backup procedure | E20: Finance | F20: Sherif Hosny | G20: Low | H20: Completed | I20: 1500 | J20: 1799 | K20: 45542 | L20: 45553 | M20: 45553 | N20: 11 | O20: 0 | P20: Delta Retail Group | Q20: Youssef Adel | R20: 150000 | S20: Operations | T20: 200 | U20: =tbl_Tasks_Clean[[#This Row],[Actual_Cost]]-tbl_Tasks_Clean[[#This Row],[Planned_Cost]] -> 299 | V20: =IFERROR(tbl_Tasks_Clean[[#This Row],[Cost_Variance]]/tbl_Tasks_Clean[[#This Row],[Planned_Cost]],0) -> 0.19933333 | W20: =IF(AND(tbl_Tasks_Clean[[#This Row],[Status]]="Completed",tbl_Tasks_Clean[[#This Row],[Delay_Days]]<=0),"On Time",IF(AND(tbl_Tasks_Clean[[#This Row],[Status]]="Completed",tbl_Tasks_Clean[[#This Row],[Delay_Days]]>0),"Late","N/A")) -> On Time | X20: {=_xlfn.IFS(tbl_Tasks_Clean[[#This Row],[Planned_Duration_Days]]<=7,"Short (<=7 days)",tbl_Tasks_Clean[[#This Row],[Planned_Duration_Days]]<=20,"Medium (8-20 days)",TRUE,"Long (>20 days)")} -> Medium (8-20 days) | Y20: =INDEX(Projects!$D:$D,MATCH(tbl_Tasks_Clean[[#This Row],[Project_ID]],Projects!$A:$A,0)) -> Youssef Adel | Z20: =IF(tbl_Tasks_Clean[[#This Row],[Delay_Days]]>0,"Delayed by "&TEXT(tbl_Tasks_Clean[[#This Row],[Delay_Days]],"0")&" days",IF(tbl_Tasks_Clean[[#This Row],[Delay_Days]]<0,"Early by "&TEXT(-tbl_Tasks_Clean[[#This Row],[Delay_Days]],"0")&" days","On schedule")) -> On schedule
A21: TSK-0122 | B21: PRJ-006 | C21: CRM Migration | D21: Audit vendor contract | E21: Finance | F21: Aya Ibrahim | G21: Medium | H21: Delayed | I21: 4000 | J21: 4369 | K21: 45472 | L21: 45485 | M21: 45497 | N21: 13 | O21: 12 | P21: BlueWave Telecom | Q21: Mona Farid | R21: 120000 | S21: Quality Assurance | T21: 250 | U21: =tbl_Tasks_Clean[[#This Row],[Actual_Cost]]-tbl_Tasks_Clean[[#This Row],[Planned_Cost]] -> 369 | V21: =IFERROR(tbl_Tasks_Clean[[#This Row],[Cost_Variance]]/tbl_Tasks_Clean[[#This Row],[Planned_Cost]],0) -> 0.09225 | W21: =IF(AND(tbl_Tasks_Clean[[#This Row],[Status]]="Completed",tbl_Tasks_Clean[[#This Row],[Delay_Days]]<=0),"On Time",IF(AND(tbl_Tasks_Clean[[#This Row],[Status]]="Completed",tbl_Tasks_Clean[[#This Row],[Delay_Days]]>0),"Late","N/A")) -> N/A | X21: {=_xlfn.IFS(tbl_Tasks_Clean[[#This Row],[Planned_Duration_Days]]<=7,"Short (<=7 days)",tbl_Tasks_Clean[[#This Row],[Planned_Duration_Days]]<=20,"Medium (8-20 days)",TRUE,"Long (>20 days)")} -> Medium (8-20 days) | Y21: =INDEX(Projects!$D:$D,MATCH(tbl_Tasks_Clean[[#This Row],[Project_ID]],Projects!$A:$A,0)) -> Mona Farid | Z21: =IF(tbl_Tasks_Clean[[#This Row],[Delay_Days]]>0,"Delayed by "&TEXT(tbl_Tasks_Clean[[#This Row],[Delay_Days]],"0")&" days",IF(tbl_Tasks_Clean[[#This Row],[Delay_Days]]<0,"Early by "&TEXT(-tbl_Tasks_Clean[[#This Row],[Delay_Days]],"0")&" days","On schedule")) -> Delayed by 12 days
A22: TSK-0101 | B22: PRJ-005 | C22: Customer Portal Upgrade | D22: Design network infrastructure | E22: Quality | F22: Aya Ibrahim | G22: Medium | H22: Completed | I22: 5000 | J22: 4772 | O22: 0 | P22: Horizon Manufacturing | Q22: Ahmed Nabil | R22: 50000 | S22: Quality Assurance | T22: 250 | U22: =tbl_Tasks_Clean[[#This Row],[Actual_Cost]]-tbl_Tasks_Clean[[#This Row],[Planned_Cost]] -> -228 | V22: =IFERROR(tbl_Tasks_Clean[[#This Row],[Cost_Variance]]/tbl_Tasks_Clean[[#This Row],[Planned_Cost]],0) -> -0.0456 | W22: =IF(AND(tbl_Tasks_Clean[[#This Row],[Status]]="Completed",tbl_Tasks_Clean[[#This Row],[Delay_Days]]<=0),"On Time",IF(AND(tbl_Tasks_Clean[[#This Row],[Status]]="Completed",tbl_Tasks_Clean[[#This Row],[Delay_Days]]>0),"Late","N/A")) -> On Time | X22: {=_xlfn.IFS(tbl_Tasks_Clean[[#This Row],[Planned_Duration_Days]]<=7,"Short (<=7 days)",tbl_Tasks_Clean[[#This Row],[Planned_Duration_Days]]<=20,"Medium (8-20 days)",TRUE,"Long (>20 days)")} -> Short (<=7 days) | Y22: =INDEX(Projects!$D:$D,MATCH(tbl_Tasks_Clean[[#This Row],[Project_ID]],Projects!$A:$A,0)) -> Ahmed Nabil | Z22: =IF(tbl_Tasks_Clean[[#This Row],[Delay_Days]]>0,"Delayed by "&TEXT(tbl_Tasks_Clean[[#This Row],[Delay_Days]],"0")&" days",IF(tbl_Tasks_Clean[[#This Row],[Delay_Days]]<0,"Early by "&TEXT(-tbl_Tasks_Clean[[#This Row],[Delay_Days]],"0")&" days","On schedule")) -> On schedule
A23: TSK-0090 | B23: PRJ-005 | C23: Customer Portal Upgrade | D23: Optimize quality checklist | E23: Marketing | F23: Farida Zaki | G23: Low | H23: Completed | I23: 10000 | J23: 7969 | K23: 45341 | L23: 45370 | M23: 45368 | N23: 29 | O23: -2 | P23: Horizon Manufacturing | Q23: Ahmed Nabil | R23: 50000 | S23: Operations | T23: 200 | U23: =tbl_Tasks_Clean[[#This Row],[Actual_Cost]]-tbl_Tasks_Clean[[#This Row],[Planned_Cost]] -> -2031 | V23: =IFERROR(tbl_Tasks_Clean[[#This Row],[Cost_Variance]]/tbl_Tasks_Clean[[#This Row],[Planned_Cost]],0) -> -0.2031 | W23: =IF(AND(tbl_Tasks_Clean[[#This Row],[Status]]="Completed",tbl_Tasks_Clean[[#This Row],[Delay_Days]]<=0),"On Time",IF(AND(tbl_Tasks_Clean[[#This Row],[Status]]="Completed",tbl_Tasks_Clean[[#This Row],[Delay_Days]]>0),"Late","N/A")) -> On Time | X23: {=_xlfn.IFS(tbl_Tasks_Clean[[#This Row],[Planned_Duration_Days]]<=7,"Short (<=7 days)",tbl_Tasks_Clean[[#This Row],[Planned_Duration_Days]]<=20,"Medium (8-20 days)",TRUE,"Long (>20 days)")} -> Long (>20 days) | Y23: =INDEX(Projects!$D:$D,MATCH(tbl_Tasks_Clean[[#This Row],[Project_ID]],Projects!$A:$A,0)) -> Ahmed Nabil | Z23: =IF(tbl_Tasks_Clean[[#This Row],[Delay_Days]]>0,"Delayed by "&TEXT(tbl_Tasks_Clean[[#This Row],[Delay_Days]],"0")&" days",IF(tbl_Tasks_Clean[[#This Row],[Delay_Days]]<0,"Early by "&TEXT(-tbl_Tasks_Clean[[#This Row],[Delay_Days]],"0")&" days","On schedule")) -> Early by 2 days
A24: TSK-0299 | B24: PRJ-015 | C24: Data Center Upgrade | D24: Configure supplier list | E24: Finance | F24: Dina Fouad | G24: High | H24: In Progress | I24: 4000 | J24: 1678 | K24: 45508 | L24: 45530 | N24: 22 | O24: 0 | P24: Internal | Q24: Nourhan Tarek | R24: 75000 | S24: Marketing | T24: 300 | U24: =tbl_Tasks_Clean[[#This Row],[Actual_Cost]]-tbl_Tasks_Clean[[#This Row],[Planned_Cost]] -> -2322 | V24: =IFERROR(tbl_Tasks_Clean[[#This Row],[Cost_Variance]]/tbl_Tasks_Clean[[#This Row],[Planned_Cost]],0) -> -0.5805 | W24: =IF(AND(tbl_Tasks_Clean[[#This Row],[Status]]="Completed",tbl_Tasks_Clean[[#This Row],[Delay_Days]]<=0),"On Time",IF(AND(tbl_Tasks_Clean[[#This Row],[Status]]="Completed",tbl_Tasks_Clean[[#This Row],[Delay_Days]]>0),"Late","N/A")) -> N/A | X24: {=_xlfn.IFS(tbl_Tasks_Clean[[#This Row],[Planned_Duration_Days]]<=7,"Short (<=7 days)",tbl_Tasks_Clean[[#This Row],[Planned_Duration_Days]]<=20,"Medium (8-20 days)",TRUE,"Long (>20 days)")} -> Long (>20 days) | Y24: =INDEX(Projects!$D:$D,MATCH(tbl_Tasks_Clean[[#This Row],[Project_ID]],Projects!$A:$A,0)) -> Nourhan Tarek | Z24: =IF(tbl_Tasks_Clean[[#This Row],[Delay_Days]]>0,"Delayed by "&TEXT(tbl_Tasks_Clean[[#This Row],[Delay_Days]],"0")&" days",IF(tbl_Tasks_Clean[[#This Row],[Delay_Days]]<0,"Early by "&TEXT(-tbl_Tasks_Clean[[#This Row],[Delay_Days]],"0")&" days","On schedule")) -> On schedule
A25: TSK-0303 | B25: PRJ-015 | C25: Data Center Upgrade | D25: Plan hardware setup | E25: Finance | F25: Farida Shawky | G25: Medium | H25: Not Started | I25: 10000 | J25: 0 | K25: 45438 | L25: 45459 | N25: 21 | O25: 0 | P25: Internal | Q25: Nourhan Tarek | R25: 75000 | S25: Procurement | T25: 250 | U25: =tbl_Tasks_Clean[[#This Row],[Actual_Cost]]-tbl_Tasks_Clean[[#This Row],[Planned_Cost]] -> -10000 | V25: =IFERROR(tbl_Tasks_Clean[[#This Row],[Cost_Variance]]/tbl_Tasks_Clean[[#This Row],[Planned_Cost]],0) -> -1 | W25: =IF(AND(tbl_Tasks_Clean[[#This Row],[Status]]="Completed",tbl_Tasks_Clean[[#This Row],[Delay_Days]]<=0),"On Time",IF(AND(tbl_Tasks_Clean[[#This Row],[Status]]="Completed",tbl_Tasks_Clean[[#This Row],[Delay_Days]]>0),"Late","N/A")) -> N/A | X25: {=_xlfn.IFS(tbl_Tasks_Clean[[#This Row],[Planned_Duration_Days]]<=7,"Short (<=7 days)",tbl_Tasks_Clean[[#This Row],[Planned_Duration_Days]]<=20,"Medium (8-20 days)",TRUE,"Long (>20 days)")} -> Long (>20 days) | Y25: =INDEX(Projects!$D:$D,MATCH(tbl_Tasks_Clean[[#This Row],[Project_ID]],Projects!$A:$A,0)) -> Nourhan Tarek | Z25: =IF(tbl_Tasks_Clean[[#This Row],[Delay_Days]]>0,"Delayed by "&TEXT(tbl_Tasks_Clean[[#This Row],[Delay_Days]],"0")&" days",IF(tbl_Tasks_Clean[[#This Row],[Delay_Days]]<0,"Early by "&TEXT(-tbl_Tasks_Clean[[#This Row],[Delay_Days]],"0")&" days","On schedule")) -> On schedule
A26: TSK-0172 | B26: PRJ-009 | C26: Supply Chain Optimization | D26: Audit user interface | E26: Quality | F26: Farida Shawky | G26: Low | H26: Completed | I26: 1500 | J26: 1823 | O26: 0 | P26: Suez Trading Co. | Q26: Laila Samir | R26: 100000 | S26: Procurement | T26: 250 | U26: =tbl_Tasks_Clean[[#This Row],[Actual_Cost]]-tbl_Tasks_Clean[[#This Row],[Planned_Cost]] -> 323 | V26: =IFERROR(tbl_Tasks_Clean[[#This Row],[Cost_Variance]]/tbl_Tasks_Clean[[#This Row],[Planned_Cost]],0) -> 0.21533333 | W26: =IF(AND(tbl_Tasks_Clean[[#This Row],[Status]]="Completed",tbl_Tasks_Clean[[#This Row],[Delay_Days]]<=0),"On Time",IF(AND(tbl_Tasks_Clean[[#This Row],[Status]]="Completed",tbl_Tasks_Clean[[#This Row],[Delay_Days]]>0),"Late","N/A")) -> On Time | X26: {=_xlfn.IFS(tbl_Tasks_Clean[[#This Row],[Planned_Duration_Days]]<=7,"Short (<=7 days)",tbl_Tasks_Clean[[#This Row],[Planned_Duration_Days]]<=20,"Medium (8-20 days)",TRUE,"Long (>20 days)")} -> Short (<=7 days) | Y26: =INDEX(Projects!$D:$D,MATCH(tbl_Tasks_Clean[[#This Row],[Project_ID]],Projects!$A:$A,0)) -> Laila Samir | Z26: =IF(tbl_Tasks_Clean[[#This Row],[Delay_Days]]>0,"Delayed by "&TEXT(tbl_Tasks_Clean[[#This Row],[Delay_Days]],"0")&" days",IF(tbl_Tasks_Clean[[#This Row],[Delay_Days]]<0,"Early by "&TEXT(-tbl_Tasks_Clean[[#This Row],[Delay_Days]],"0")&" days","On schedule")) -> On schedule
A27: TSK-0150 | B27: PRJ-008 | C27: Office Relocation | D27: Develop training material | E27: Finance | F27: Mariam Kamal | G27: High | H27: Delayed | I27: 1000 | J27: 1347 | K27: 45493 | L27: 45511 | M27: 45516 | N27: 18 | O27: 5 | P27: Pharos Holdings | Q27: Nourhan Tarek | R27: 300000 | S27: Procurement | T27: 180 | U27: =tbl_Tasks_Clean[[#This Row],[Actual_Cost]]-tbl_Tasks_Clean[[#This Row],[Planned_Cost]] -> 347 | V27: =IFERROR(tbl_Tasks_Clean[[#This Row],[Cost_Variance]]/tbl_Tasks_Clean[[#This Row],[Planned_Cost]],0) -> 0.347 | W27: =IF(AND(tbl_Tasks_Clean[[#This Row],[Status]]="Completed",tbl_Tasks_Clean[[#This Row],[Delay_Days]]<=0),"On Time",IF(AND(tbl_Tasks_Clean[[#This Row],[Status]]="Completed",tbl_Tasks_Clean[[#This Row],[Delay_Days]]>0),"Late","N/A")) -> N/A | X27: {=_xlfn.IFS(tbl_Tasks_Clean[[#This Row],[Planned_Duration_Days]]<=7,"Short (<=7 days)",tbl_Tasks_Clean[[#This Row],[Planned_Duration_Days]]<=20,"Medium (8-20 days)",TRUE,"Long (>20 days)")} -> Medium (8-20 days) | Y27: =INDEX(Projects!$D:$D,MATCH(tbl_Tasks_Clean[[#This Row],[Project_ID]],Projects!$A:$A,0)) -> Nourhan Tarek | Z27: =IF(tbl_Tasks_Clean[[#This Row],[Delay_Days]]>0,"Delayed by "&TEXT(tbl_Tasks_Clean[[#This Row],[Delay_Days]],"0")&" days",IF(tbl_Tasks_Clean[[#This Row],[Delay_Days]]<0,"Early by "&TEXT(-tbl_Tasks_Clean[[#This Row],[Delay_Days]],"0")&" days","On schedule")) -> Delayed by 5 days
A28: TSK-0149 | B28: PRJ-008 | C28: Office Relocation | D28: Test API integration | E28: Quality | F28: Sherif Ibrahim | G28: Medium | H28: Not Started | I28: 1000 | J28: 0 | O28: 0 | P28: Pharos Holdings | Q28: Nourhan Tarek | R28: 300000 | S28: Procurement | T28: 180 | U28: =tbl_Tasks_Clean[[#This Row],[Actual_Cost]]-tbl_Tasks_Clean[[#This Row],[Planned_Cost]] -> -1000 | V28: =IFERROR(tbl_Tasks_Clean[[#This Row],[Cost_Variance]]/tbl_Tasks_Clean[[#This Row],[Planned_Cost]],0) -> -1 | W28: =IF(AND(tbl_Tasks_Clean[[#This Row],[Status]]="Completed",tbl_Tasks_Clean[[#This Row],[Delay_Days]]<=0),"On Time",IF(AND(tbl_Tasks_Clean[[#This Row],[Status]]="Completed",tbl_Tasks_Clean[[#This Row],[Delay_Days]]>0),"Late","N/A")) -> N/A | X28: {=_xlfn.IFS(tbl_Tasks_Clean[[#This Row],[Planned_Duration_Days]]<=7,"Short (<=7 days)",tbl_Tasks_Clean[[#This Row],[Planned_Duration_Days]]<=20,"Medium (8-20 days)",TRUE,"Long (>20 days)")} -> Short (<=7 days) | Y28: =INDEX(Projects!$D:$D,MATCH(tbl_Tasks_Clean[[#This Row],[Project_ID]],Projects!$A:$A,0)) -> Nourhan Tarek | Z28: =IF(tbl_Tasks_Clean[[#This Row],[Delay_Days]]>0,"Delayed by "&TEXT(tbl_Tasks_Clean[[#This Row],[Delay_Days]],"0")&" days",IF(tbl_Tasks_Clean[[#This Row],[Delay_Days]]<0,"Early by "&TEXT(-tbl_Tasks_Clean[[#This Row],[Delay_Days]],"0")&" days","On schedule")) -> On schedule
A29: TSK-0198 | B29: PRJ-010 | C29: Product Line Expansion | D29: Plan database schema | E29: IT | F29: Unassigned | G29: High | H29: Completed | I29: 8000 | J29: 5874 | K29: 45442 | L29: 45456 | M29: 45456 | N29: 14 | O29: 0 | P29: Internal | Q29: Sara Hassan | R29: 150000 | U29: =tbl_Tasks_Clean[[#This Row],[Actual_Cost]]-tbl_Tasks_Clean[[#This Row],[Planned_Cost]] -> -2126 | V29: =IFERROR(tbl_Tasks_Clean[[#This Row],[Cost_Variance]]/tbl_Tasks_Clean[[#This Row],[Planned_Cost]],0) -> -0.26575 | W29: =IF(AND(tbl_Tasks_Clean[[#This Row],[Status]]="Completed",tbl_Tasks_Clean[[#This Row],[Delay_Days]]<=0),"On Time",IF(AND(tbl_Tasks_Clean[[#This Row],[Status]]="Completed",tbl_Tasks_Clean[[#This Row],[Delay_Days]]>0),"Late","N/A")) -> On Time | X29: {=_xlfn.IFS(tbl_Tasks_Clean[[#This Row],[Planned_Duration_Days]]<=7,"Short (<=7 days)",tbl_Tasks_Clean[[#This Row],[Planned_Duration_Days]]<=20,"Medium (8-20 days)",TRUE,"Long (>20 days)")} -> Medium (8-20 days) | Y29: =INDEX(Projects!$D:$D,MATCH(tbl_Tasks_Clean[[#This Row],[Project_ID]],Projects!$A:$A,0)) -> Sara Hassan | Z29: =IF(tbl_Tasks_Clean[[#This Row],[Delay_Days]]>0,"Delayed by "&TEXT(tbl_Tasks_Clean[[#This Row],[Delay_Days]],"0")&" days",IF(tbl_Tasks_Clean[[#This Row],[Delay_Days]]<0,"Early by "&TEXT(-tbl_Tasks_Clean[[#This Row],[Delay_Days]],"0")&" days","On schedule")) -> On schedule
A30: TSK-0119 | B30: PRJ-006 | C30: CRM Migration | D30: Document user interface | E30: Quality | F30: Ziad Abdelrahman | G30: Medium | H30: Done | I30: 10000 | J30: 12422 | O30: 0 | P30: BlueWave Telecom | Q30: Mona Farid | R30: 120000 | S30: Finance | T30: 220 | U30: =tbl_Tasks_Clean[[#This Row],[Actual_Cost]]-tbl_Tasks_Clean[[#This Row],[Planned_Cost]] -> 2422 | V30: =IFERROR(tbl_Tasks_Clean[[#This Row],[Cost_Variance]]/tbl_Tasks_Clean[[#This Row],[Planned_Cost]],0) -> 0.2422 | W30: =IF(AND(tbl_Tasks_Clean[[#This Row],[Status]]="Completed",tbl_Tasks_Clean[[#This Row],[Delay_Days]]<=0),"On Time",IF(AND(tbl_Tasks_Clean[[#This Row],[Status]]="Completed",tbl_Tasks_Clean[[#This Row],[Delay_Days]]>0),"Late","N/A")) -> N/A | X30: {=_xlfn.IFS(tbl_Tasks_Clean[[#This Row],[Planned_Duration_Days]]<=7,"Short (<=7 days)",tbl_Tasks_Clean[[#This Row],[Planned_Duration_Days]]<=20,"Medium (8-20 days)",TRUE,"Long (>20 days)")} -> Short (<=7 days) | Y30: =INDEX(Projects!$D:$D,MATCH(tbl_Tasks_Clean[[#This Row],[Project_ID]],Projects!$A:$A,0)) -> Mona Farid | Z30: =IF(tbl_Tasks_Clean[[#This Row],[Delay_Days]]>0,"Delayed by "&TEXT(tbl_Tasks_Clean[[#This Row],[Delay_Days]],"0")&" days",IF(tbl_Tasks_Clean[[#This Row],[Delay_Days]]<0,"Early by "&TEXT(-tbl_Tasks_Clean[[#This Row],[Delay_Days]],"0")&" days","On schedule")) -> On schedule
A31: TSK-0304 | B31: PRJ-015 | C31: Data Center Upgrade | D31: Approve budget report | E31: Marketing | F31: Khaled Naguib | G31: Low | H31: Delayed | I31: 2000 | J31: 2297 | K31: 45506 | L31: 45529 | M31: 45530 | N31: 23 | O31: 1 | P31: Internal | Q31: Nourhan Tarek | R31: 75000 | S31: Finance | T31: 250 | U31: =tbl_Tasks_Clean[[#This Row],[Actual_Cost]]-tbl_Tasks_Clean[[#This Row],[Planned_Cost]] -> 297 | V31: =IFERROR(tbl_Tasks_Clean[[#This Row],[Cost_Variance]]/tbl_Tasks_Clean[[#This Row],[Planned_Cost]],0) -> 0.1485 | W31: =IF(AND(tbl_Tasks_Clean[[#This Row],[Status]]="Completed",tbl_Tasks_Clean[[#This Row],[Delay_Days]]<=0),"On Time",IF(AND(tbl_Tasks_Clean[[#This Row],[Status]]="Completed",tbl_Tasks_Clean[[#This Row],[Delay_Days]]>0),"Late","N/A")) -> N/A | X31: {=_xlfn.IFS(tbl_Tasks_Clean[[#This Row],[Planned_Duration_Days]]<=7,"Short (<=7 days)",tbl_Tasks_Clean[[#This Row],[Planned_Duration_Days]]<=20,"Medium (8-20 days)",TRUE,"Long (>20 days)")} -> Long (>20 days) | Y31: =INDEX(Projects!$D:$D,MATCH(tbl_Tasks_Clean[[#This Row],[Project_ID]],Projects!$A:$A,0)) -> Nourhan Tarek | Z31: =IF(tbl_Tasks_Clean[[#This Row],[Delay_Days]]>0,"Delayed by "&TEXT(tbl_Tasks_Clean[[#This Row],[Delay_Days]],"0")&" days",IF(tbl_Tasks_Clean[[#This Row],[Delay_Days]]<0,"Early by "&TEXT(-tbl_Tasks_Clean[[#This Row],[Delay_Days]],"0")&" days","On schedule")) -> Delayed by 1 days
A32: TSK-0048 | B32: PRJ-003 | C32: Mobile App Launch | D32: Install vendor contract | E32: IT | F32: Salma Fouad | G32: Medium | H32: Completed | I32: 1500 | J32: 1286 | K32: 45352 | L32: 45372 | M32: 45372 | N32: 20 | O32: 0 | P32: Alexandria Logistics | Q32: Ahmed Nabil | R32: 100000 | S32: Quality Assurance | T32: 200 | U32: =tbl_Tasks_Clean[[#This Row],[Actual_Cost]]-tbl_Tasks_Clean[[#This Row],[Planned_Cost]] -> -214 | V32: =IFERROR(tbl_Tasks_Clean[[#This Row],[Cost_Variance]]/tbl_Tasks_Clean[[#This Row],[Planned_Cost]],0) -> -0.14266667 | W32: =IF(AND(tbl_Tasks_Clean[[#This Row],[Status]]="Completed",tbl_Tasks_Clean[[#This Row],[Delay_Days]]<=0),"On Time",IF(AND(tbl_Tasks_Clean[[#This Row],[Status]]="Completed",tbl_Tasks_Clean[[#This Row],[Delay_Days]]>0),"Late","N/A")) -> On Time | X32: {=_xlfn.IFS(tbl_Tasks_Clean[[#This Row],[Planned_Duration_Days]]<=7,"Short (<=7 days)",tbl_Tasks_Clean[[#This Row],[Planned_Duration_Days]]<=20,"Medium (8-20 days)",TRUE,"Long (>20 days)")} -> Medium (8-20 days) | Y32: =INDEX(Projects!$D:$D,MATCH(tbl_Tasks_Clean[[#This Row],[Project_ID]],Projects!$A:$A,0)) -> Ahmed Nabil | Z32: =IF(tbl_Tasks_Clean[[#This Row],[Delay_Days]]>0,"Delayed by "&TEXT(tbl_Tasks_Clean[[#This Row],[Delay_Days]],"0")&" days",IF(tbl_Tasks_Clean[[#This Row],[Delay_Days]]<0,"Early by "&TEXT(-tbl_Tasks_Clean[[#This Row],[Delay_Days]],"0")&" days","On schedule")) -> On schedule
A33: TSK-0051 | B33: PRJ-003 | C33: Mobile App Launch | D33: Approve onboarding process | E33: HR | F33: Mostafa El-Sayed | G33: High | H33: Completed | I33: 5000 | J33: 3653 | K33: 45495 | L33: 45510 | M33: 45508 | N33: 15 | O33: -2 | P33: Alexandria Logistics | Q33: Ahmed Nabil | R33: 100000 | S33: Procurement | T33: 200 | U33: =tbl_Tasks_Clean[[#This Row],[Actual_Cost]]-tbl_Tasks_Clean[[#This Row],[Planned_Cost]] -> -1347 | V33: =IFERROR(tbl_Tasks_Clean[[#This Row],[Cost_Variance]]/tbl_Tasks_Clean[[#This Row],[Planned_Cost]],0) -> -0.2694 | W33: =IF(AND(tbl_Tasks_Clean[[#This Row],[Status]]="Completed",tbl_Tasks_Clean[[#This Row],[Delay_Days]]<=0),"On Time",IF(AND(tbl_Tasks_Clean[[#This Row],[Status]]="Completed",tbl_Tasks_Clean[[#This Row],[Delay_Days]]>0),"Late","N/A")) -> On Time | X33: {=_xlfn.IFS(tbl_Tasks_Clean[[#This Row],[Planned_Duration_Days]]<=7,"Short (<=7 days)",tbl_Tasks_Clean[[#This Row],[Planned_Duration_Days]]<=20,"Medium (8-20 days)",TRUE,"Long (>20 days)")} -> Medium (8-20 days) | Y33: =INDEX(Projects!$D:$D,MATCH(tbl_Tasks_Clean[[#This Row],[Project_ID]],Projects!$A:$A,0)) -> Ahmed Nabil | Z33: =IF(tbl_Tasks_Clean[[#This Row],[Delay_Days]]>0,"Delayed by "&TEXT(tbl_Tasks_Clean[[#This Row],[Delay_Days]],"0")&" days",IF(tbl_Tasks_Clean[[#This Row],[Delay_Days]]<0,"Early by "&TEXT(-tbl_Tasks_Clean[[#This Row],[Delay_Days]],"0")&" days","On schedule")) -> Early by 2 days
A34: TSK-0068 | B34: PRJ-004 | C34: Warehouse Automation | D34: Review API integration | E34: IT | F34: Ziad Abdelrahman | G34: High | H34: Done | I34: 1000 | J34: 1399 | K34: 45582 | L34: 45605 | M34: 45602 | N34: 23 | O34: -3 | P34: Cairo Financial Services | Q34: Laila Samir | R34: 75000 | S34: Finance | T34: 220 | U34: =tbl_Tasks_Clean[[#This Row],[Actual_Cost]]-tbl_Tasks_Clean[[#This Row],[Planned_Cost]] -> 399 | V34: =IFERROR(tbl_Tasks_Clean[[#This Row],[Cost_Variance]]/tbl_Tasks_Clean[[#This Row],[Planned_Cost]],0) -> 0.399 | W34: =IF(AND(tbl_Tasks_Clean[[#This Row],[Status]]="Completed",tbl_Tasks_Clean[[#This Row],[Delay_Days]]<=0),"On Time",IF(AND(tbl_Tasks_Clean[[#This Row],[Status]]="Completed",tbl_Tasks_Clean[[#This Row],[Delay_Days]]>0),"Late","N/A")) -> N/A | X34: {=_xlfn.IFS(tbl_Tasks_Clean[[#This Row],[Planned_Duration_Days]]<=7,"Short (<=7 days)",tbl_Tasks_Clean[[#This Row],[Planned_Duration_Days]]<=20,"Medium (8-20 days)",TRUE,"Long (>20 days)")} -> Long (>20 days) | Y34: =INDEX(Projects!$D:$D,MATCH(tbl_Tasks_Clean[[#This Row],[Project_ID]],Projects!$A:$A,0)) -> Laila Samir | Z34: =IF(tbl_Tasks_Clean[[#This Row],[Delay_Days]]>0,"Delayed by "&TEXT(tbl_Tasks_Clean[[#This Row],[Delay_Days]],"0")&" days",IF(tbl_Tasks_Clean[[#This Row],[Delay_Days]]<0,"Early by "&TEXT(-tbl_Tasks_Clean[[#This Row],[Delay_Days]],"0")&" days","On schedule")) -> Early by 3 days
A35: TSK-0307 | B35: PRJ-015 | C35: Data Center Upgrade | D35: Deploy server configuration | E35: IT | F35: Noor Naguib | G35: High | H35: In Progress | I35: 2500 | J35: 1606 | O35: 0 | P35: Internal | Q35: Nourhan Tarek | R35: 75000 | S35: Marketing | T35: 280 | U35: =tbl_Tasks_Clean[[#This Row],[Actual_Cost]]-tbl_Tasks_Clean[[#This Row],[Planned_Cost]] -> -894 | V35: =IFERROR(tbl_Tasks_Clean[[#This Row],[Cost_Variance]]/tbl_Tasks_Clean[[#This Row],[Planned_Cost]],0) -> -0.3576 | W35: =IF(AND(tbl_Tasks_Clean[[#This Row],[Status]]="Completed",tbl_Tasks_Clean[[#This Row],[Delay_Days]]<=0),"On Time",IF(AND(tbl_Tasks_Clean[[#This Row],[Status]]="Completed",tbl_Tasks_Clean[[#This Row],[Delay_Days]]>0),"Late","N/A")) -> N/A | X35: {=_xlfn.IFS(tbl_Tasks_Clean[[#This Row],[Planned_Duration_Days]]<=7,"Short (<=7 days)",tbl_Tasks_Clean[[#This Row],[Planned_Duration_Days]]<=20,"Medium (8-20 days)",TRUE,"Long (>20 days)")} -> Short (<=7 days) | Y35: =INDEX(Projects!$D:$D,MATCH(tbl_Tasks_Clean[[#This Row],[Project_ID]],Projects!$A:$A,0)) -> Nourhan Tarek | Z35: =IF(tbl_Tasks_Clean[[#This Row],[Delay_Days]]>0,"Delayed by "&TEXT(tbl_Tasks_Clean[[#This Row],[Delay_Days]],"0")&" days",IF(tbl_Tasks_Clean[[#This Row],[Delay_Days]]<0,"Early by "&TEXT(-tbl_Tasks_Clean[[#This Row],[Delay_Days]],"0")&" days","On schedule")) -> On schedule
